<mujoco model="ur5e">
  <compiler angle="radian" meshdir="assets" autolimits="true"/>

  <option integrator="implicitfast"/>

  <default>
    <default class="ur5e">
      <material specular="0.5" shininess="0.25"/>
      <joint axis="0 1 0" range="-6.28319 6.28319" armature="0.1"/>
      <general gaintype="fixed" biastype="affine" ctrlrange="-6.2831 6.2831" gainprm="2000" biasprm="0 -2000 -400"
        forcerange="-150 150"/>
      <default class="size3">
        <default class="size3_limited">
          <joint range="-3.1415 3.1415"/>
          <general ctrlrange="-3.1415 3.1415"/>
        </default>
      </default>
      <default class="size1">
        <general gainprm="500" biasprm="0 -500 -100" forcerange="-28 28"/>
      </default>
      <default class="visual">
        <geom type="mesh" contype="0" conaffinity="0" group="2"/>
      </default>
      <default class="collision">
        <geom type="capsule" group="3"/>
        <default class="eef_collision">
          <geom type="cylinder"/>
        </default>
      </default>
      <site size="0.001" rgba="0.5 0.5 0.5 0.3" group="4"/>
    </default>
    <default class="d435i">
      <material specular="0" shininess="0.25"/>
    </default>
    <!-- D435i geom classes (prefixed to avoid collision with Aubo names) -->
    <default class="d435i_vis">
      <geom group="2" type="mesh" contype="0" conaffinity="0" mass="0"/>
    </default>
    <default class="d435i_col">
      <geom group="3" type="mesh" mass="0"/>
    </default>
  </default>

  <asset>
    <material class="ur5e" name="black" rgba="0.033 0.033 0.033 1"/>
    <material class="ur5e" name="jointgray" rgba="0.278 0.278 0.278 1"/>
    <material class="ur5e" name="linkgray" rgba="0.82 0.82 0.82 1"/>
    <material class="ur5e" name="urblue" rgba="0.49 0.678 0.8 1"/>

    <mesh file="base_0.obj"/>
    <mesh file="base_1.obj"/>
    <mesh file="shoulder_0.obj"/>
    <mesh file="shoulder_1.obj"/>
    <mesh file="shoulder_2.obj"/>
    <mesh file="upperarm_0.obj"/>
    <mesh file="upperarm_1.obj"/>
    <mesh file="upperarm_2.obj"/>
    <mesh file="upperarm_3.obj"/>
    <mesh file="forearm_0.obj"/>
    <mesh file="forearm_1.obj"/>
    <mesh file="forearm_2.obj"/>
    <mesh file="forearm_3.obj"/>
    <mesh file="wrist1_0.obj"/>
    <mesh file="wrist1_1.obj"/>
    <mesh file="wrist1_2.obj"/>
    <mesh file="wrist2_0.obj"/>
    <mesh file="wrist2_1.obj"/>
    <mesh file="wrist2_2.obj"/>
    <mesh file="wrist3.obj"/>

    <!-- D435i materials (inherit specular/shininess from "d435i" class) -->
    <material class="d435i" name="Black_Acrylic"    rgba="0.070360 0.070360 0.070360 1"/>
    <material class="d435i" name="Cameras_Gray"     rgba="0.296138 0.296138 0.296138 1"/>
    <material class="d435i" name="IR_Emitter_Lens"  rgba="0.287440 0.665387 0.327778 1"/>
    <material class="d435i" name="IR_Lens"          rgba="0.035601 0.035601 0.035601 1"/>
    <material class="d435i" name="IR_Rim"           rgba="0.799102 0.806952 0.799103 1"/>
    <material class="d435i" name="Metal_Casing"     rgba="1 1 1 1"/>
    <material class="d435i" name="RGB_Pupil"        rgba="0.087140 0.002866 0.009346 1"/>
    <material name="gripper_2f85_metal" rgba="0.58 0.58 0.58 1"/>
    <material name="gripper_2f85_silicone" rgba="0.1882 0.1882 0.1882 1"/>
    <material name="gripper_2f85_gray" rgba="0.4627 0.4627 0.4627 1"/>
    <material name="gripper_2f85_black" rgba="0.149 0.149 0.149 1"/>

    <!-- D435i meshes (in realsense/ subdirectory next to this file) -->
    <mesh name="d435i_0" file="d435i_0.obj"/>
    <mesh name="d435i_1" file="d435i_1.obj"/>
    <mesh name="d435i_2" file="d435i_2.obj"/>
    <mesh name="d435i_3" file="d435i_3.obj"/>
    <mesh name="d435i_4" file="d435i_4.obj"/>
    <mesh name="d435i_5" file="d435i_5.obj"/>
    <mesh name="d435i_6" file="d435i_6.obj"/>
    <mesh name="d435i_7" file="d435i_7.obj"/>
    <mesh name="d435i_8" file="d435i_8.obj"/>

    <mesh name="tool" file="tool_hd.stl" scale="0.001 0.001 0.001"/>
    <mesh name="gripper_2f85_base_mount" file="robotiq_2f85/base_mount.stl" scale="0.001 0.001 0.001"/>
    <mesh name="gripper_2f85_base" file="robotiq_2f85/base.stl" scale="0.001 0.001 0.001"/>
    <mesh name="gripper_2f85_driver" file="robotiq_2f85/driver.stl" scale="0.001 0.001 0.001"/>
    <mesh name="gripper_2f85_coupler" file="robotiq_2f85/coupler.stl" scale="0.001 0.001 0.001"/>
    <mesh name="gripper_2f85_follower" file="robotiq_2f85/follower.stl" scale="0.001 0.001 0.001"/>
    <mesh name="gripper_2f85_pad" file="robotiq_2f85/pad.stl" scale="0.001 0.001 0.001"/>
    <mesh name="gripper_2f85_silicone_pad" file="robotiq_2f85/silicone_pad.stl" scale="0.001 0.001 0.001"/>
    <mesh name="gripper_2f85_spring_link" file="robotiq_2f85/spring_link.stl" scale="0.001 0.001 0.001"/>

    <mesh name="egp_base" content_type="model/obj" file="egp_base.obj"/>
    <mesh name="egp_trans_1" content_type="model/obj" file="egp_trans_1.obj"/>
    <mesh name="egp_trans_2" content_type="model/obj" file="egp_trans_2.obj"/>
  </asset>

  <worldbody>
    <light name="spotlight" mode="targetbodycom" target="wrist_2_link" pos="0 -1 2"/>
    <body name="base" quat="0 0 0 -1" childclass="ur5e">
      <inertial mass="4.0" pos="0 0 0" diaginertia="0.00443333156 0.00443333156 0.0072"/>
      <geom mesh="base_0" material="black" class="visual"/>
      <geom mesh="base_1" material="jointgray" class="visual"/>
      <body name="shoulder_link" pos="0 0 0.163">
        <inertial mass="3.7" pos="0 0 0" diaginertia="0.0102675 0.0102675 0.00666"/>
        <joint name="shoulder_pan_joint" class="size3" axis="0 0 1"/>
        <geom mesh="shoulder_0" material="urblue" class="visual"/>
        <geom mesh="shoulder_1" material="black" class="visual"/>
        <geom mesh="shoulder_2" material="jointgray" class="visual"/>
        <geom class="collision" size="0.06 0.06" pos="0 0 -0.04"/>
        <body name="upper_arm_link" pos="0 0.138 0" quat="1 0 1 0">
          <inertial mass="8.393" pos="0 0 0.2125" diaginertia="0.133886 0.133886 0.0151074"/>
          <joint name="shoulder_lift_joint" class="size3"/>
          <geom mesh="upperarm_0" material="linkgray" class="visual"/>
          <geom mesh="upperarm_1" material="black" class="visual"/>
          <geom mesh="upperarm_2" material="jointgray" class="visual"/>
          <geom mesh="upperarm_3" material="urblue" class="visual"/>
          <geom class="collision" pos="0 -0.04 0" quat="1 1 0 0" size="0.06 0.06"/>
          <geom class="collision" size="0.05 0.2" pos="0 0 0.2"/>
          <body name="forearm_link" pos="0 -0.131 0.425">
            <inertial mass="2.275" pos="0 0 0.196" diaginertia="0.0311796 0.0311796 0.004095"/>
            <joint name="elbow_joint" class="size3_limited"/>
            <geom mesh="forearm_0" material="urblue" class="visual"/>
            <geom mesh="forearm_1" material="linkgray" class="visual"/>
            <geom mesh="forearm_2" material="black" class="visual"/>
            <geom mesh="forearm_3" material="jointgray" class="visual"/>
            <geom class="collision" pos="0 0.08 0" quat="1 1 0 0" size="0.055 0.06"/>
            <geom class="collision" size="0.038 0.19" pos="0 0 0.2"/>
            <body name="wrist_1_link" pos="0 0 0.392" quat="1 0 1 0">
              <inertial mass="1.219" pos="0 0.127 0" diaginertia="0.0025599 0.0025599 0.0021942"/>
              <joint name="wrist_1_joint" class="size1"/>
              <geom mesh="wrist1_0" material="black" class="visual"/>
              <geom mesh="wrist1_1" material="urblue" class="visual"/>
              <geom mesh="wrist1_2" material="jointgray" class="visual"/>
              <geom class="collision" pos="0 0.05 0" quat="1 1 0 0" size="0.04 0.07"/>
              <body name="wrist_2_link" pos="0 0.127 0">
                <inertial mass="1.219" pos="0 0 0.1" diaginertia="0.0025599 0.0025599 0.0021942"/>
                <joint name="wrist_2_joint" axis="0 0 1" class="size1"/>
                <geom mesh="wrist2_0" material="black" class="visual"/>
                <geom mesh="wrist2_1" material="urblue" class="visual"/>
                <geom mesh="wrist2_2" material="jointgray" class="visual"/>
                <geom class="collision" size="0.04 0.06" pos="0 0 0.04"/>
                <geom class="collision" pos="0 0.02 0.1" quat="1 1 0 0" size="0.04 0.04"/>
                <body name="wrist_3_link" pos="0 0 0.1">
                  <inertial mass="0.1889" pos="0 0.0771683 0" quat="1 0 0 1"
                    diaginertia="0.000132134 9.90863e-05 9.90863e-05"/>
                  <joint name="wrist_3_joint" class="size1"/>
                  <geom material="linkgray" mesh="wrist3" class="visual"/>
                  <geom class="eef_collision" pos="0 0.08 0" quat="1 1 0 0" size="0.04 0.02"/>
                  <site name="attachment_site" pos="0 0.0 0" quat="-1 1 0 0"/>
                    <body name="cam_mount_body" pos="0 0 0" >
                      <body name="tool" pos="0.0 0.0 0" >
                        <geom mesh="tool" class="visual" euler="0 1.5704 1.5704" pos= "0.0 0.10 0.0"/>
                        <geom mesh="tool" class="collision" euler="0 1.5704 1.5704" pos= "0.0 0.10 0"/>
                        <body name="gripper_2f85_mount" pos="0.0 0.10 0.0" euler="-1.5704 0 0">
                          <include file="2f85_component.xml"/>
                        </body>
                          <body name="d435i" childclass="d435i"
                            pos="0 0.135 0.095"
                            euler="-1.5704 0 0 ">

                        <!-- Visual mesh components (no collision) -->
                          <geom mesh="d435i_0" material="IR_Lens"         class="d435i_vis"/>
                          <geom mesh="d435i_1" material="IR_Emitter_Lens" class="d435i_vis"/>
                          <geom mesh="d435i_2" material="IR_Rim"          class="d435i_vis"/>
                          <geom mesh="d435i_3" material="IR_Lens"         class="d435i_vis"/>
                          <geom mesh="d435i_4" material="Cameras_Gray"    class="d435i_vis"/>
                          <geom mesh="d435i_5" material="Black_Acrylic"   class="d435i_vis"/>
                          <geom mesh="d435i_6" material="Black_Acrylic"   class="d435i_vis"/>
                          <geom mesh="d435i_7" material="RGB_Pupil"       class="d435i_vis"/>
                          <geom mesh="d435i_8" mass="0.072"
                              material="Metal_Casing"                   class="d435i_vis"/>

                        <!-- Capsule collision (auto-fitted to d435i_8 via fitaabb) -->
                          <geom class="d435i_col" type="capsule" mesh="d435i_8"/>

                        <!-- RGB camera sensor inside the RGB_Pupil (d435i_7).
                             pos  = centre of the RGB_Pupil mesh in d435i body frame
                                    (measured from compiled geometry: x=0.0325, z=-0.0036)
                             fovy = D435i RGB vertical FOV ≈ 42 °
                        -->
                          <camera name="real_sense"
                                pos="-0.01 0 -0.0036"
                                euler="-3.14 0 0"
                                fovy="54"
                                resolution="640 480"/>
                        </body><!-- d435i -->
                        
                      <site name="eef_site" pos="0.01 0.11 0.1" euler="-1.5704 0 0" group="3"/>

                        </body>

                    </body><!-- cam_mount_body -->
                </body>
              </body>
            </body>
          </body>
        </body>
      </body>
    </body>
  </worldbody>

  <contact>
    <exclude body1="gripper_2f85_base" body2="gripper_2f85_left_driver"/>
    <exclude body1="gripper_2f85_base" body2="gripper_2f85_right_driver"/>
    <exclude body1="gripper_2f85_base" body2="gripper_2f85_left_spring_link"/>
    <exclude body1="gripper_2f85_base" body2="gripper_2f85_right_spring_link"/>
    <exclude body1="gripper_2f85_right_coupler" body2="gripper_2f85_right_follower"/>
    <exclude body1="gripper_2f85_left_coupler" body2="gripper_2f85_left_follower"/>
  </contact>

  <tendon>
    <fixed name="gripper_2f85_split">
      <joint joint="gripper_2f85_right_driver_joint" coef="0.5"/>
      <joint joint="gripper_2f85_left_driver_joint" coef="0.5"/>
    </fixed>
  </tendon>

  <equality>
    <connect anchor="0 0 0" body1="gripper_2f85_right_follower" body2="gripper_2f85_right_coupler"/>
    <connect anchor="0 0 0" body1="gripper_2f85_left_follower" body2="gripper_2f85_left_coupler"/>
    <joint joint1="gripper_2f85_right_driver_joint" joint2="gripper_2f85_left_driver_joint"
      polycoef="0 1 0 0 0"/>
  </equality>

  <actuator>
    <motor name="shoulder_pan" joint="shoulder_pan_joint"/>
    <motor  name="shoulder_lift" joint="shoulder_lift_joint"/>
    <motor name="elbow" joint="elbow_joint"/>
    <motor name="wrist_1" joint="wrist_1_joint"/>
    <motor name="wrist_2" joint="wrist_2_joint"/>
    <motor name="wrist_3" joint="wrist_3_joint"/>
    <general name="gripper_2f85_fingers_actuator" tendon="gripper_2f85_split"
      forcerange="-5 5" ctrlrange="0 255"
      gainprm="0.3137255 0 0" biasprm="0 -100 -10"/>
    <!-- <general class="size1" name="shoulder_pan_vel"  joint="egp_prismatic_1" />
    <general class="size1" name="shoulder_lift_vel" joint="egp_prismatic_2" /> -->
  </actuator>

  <keyframe>
    <key name="home" qpos="-1.5708 -1.5708 1.5708 -1.5708 -1.5708 0" ctrl="-1.5708 -1.5708 1.5708 -1.5708 -1.5708 0"/>
  </keyframe>

  
</mujoco>
